# // 非重入期约方法与传递参数和拒绝理由

#### // 非重入期约方法-------------------------------------

非重入期约方法一共涉及四个,then()方法中的onResolve()和onReject(),catch(),finally(),执行到他们时会将其推入到消息队列中,然后继续执行他们后面的代码.

```JavaScript
let p=new Promise((resolve,reject)=>{resolve(7)})

p.then(()=>console.log("onResolve 后执行"))

console.log("先执行");
```

![image-20220927085935558](C:\Users\35392\AppData\Roaming\Typora\typora-user-images\image-20220927085935558.png)

###### // 在尝试onReject,catch和finally

```JavaScript
// 新建一个reject状态的p用作父级期约
let p=Promise.reject("foo")
p.then(null,(e)=>console.log("onReject 后执行"))
p.catch((e)=>console.log("catch 后执行"))
p.finally(()=>console.log("finally 后执行"))

console.log("先执行");
// 可以发现非重入的执行顺序自上而下

```

![image-20220927090108681](C:\Users\35392\AppData\Roaming\Typora\typora-user-images\image-20220927090108681.png)



#### 

---

#### 拒绝期约与期约错误处理

// 期约在状态改变的时候会产生一个值或者产生一个拒绝理由,这个理由可以被处理函数接收到

```JavaScript
let p1=new Promise((resolve,reject)=>resolve(7))
p1.then((e)=>console.log(e))

let p2=Promise.reject(new Error("foo"))
p2.catch((e)=>console.log(e))
```

![image-20220928082922954](C:\Users\35392\AppData\Roaming\Typora\typora-user-images\image-20220928082922954.png)



// 拒绝期约类似于throw(),因为他们都代表一种**程序状态**,也就是需要中断或者处理

```JavaScript
let p1=Promise.reject(Error("foo"))
let p2=new Promise((resolve,reject)=>{throw Error("foo")})
let p3=Promise.resolve().then(()=>{throw Error("bar")})


setTimeout(console.log,0,p1)
setTimeout(console.log,0,p2)
setTimeout(console.log,0,p3)
```

![image-20220928082958361](C:\Users\35392\AppData\Roaming\Typora\typora-user-images\image-20220928082958361.png)

// 最好用对象来代表拒绝理由,因为使用对象作为拒绝理由会让浏览器捕获错误对象中的栈追踪信息,更加有利于调试

```javascript
let p1=Promise.reject("foo")
let p2=Promise.reject(Error("foo"))

setTimeout(console.log,0,p1)
setTimeout(console.log,0,p2)
```

![image-20220928083113512](C:\Users\35392\AppData\Roaming\Typora\typora-user-images\image-20220928083113512.png)

// 异常与拒绝期约在上下文中的执行顺序不同,异常被检测出后会直接停止程序的运行,拒绝期约会继续下面的代码执行

```javascript
throw "foo";
console.log("bar");

```

![image-20220928083345764](C:\Users\35392\AppData\Roaming\Typora\typora-user-images\image-20220928083345764.png)



```javascript

let p1=Promise.reject(Error("foo"))
// 由于错误实际在消息队列中异步抛出的,下面的代码仍能执行
console.log("仍能执行");
```

![image-20220928083326453](C:\Users\35392\AppData\Roaming\Typora\typora-user-images\image-20220928083326453.png)

// 同样异步错误只能异步捕获



```javascript
try{
  let p1=Promise.reject(Error("foo"))
}catch(e){
  console.log(e);
}
// 使用普通的try...catch语句无法捕获

let p2=Promise.reject(Error("foo"))
p2.catch((e)=>console.log(e))
// 捕获成功
```

![image-20220928083536728](C:\Users\35392\AppData\Roaming\Typora\typora-user-images\image-20220928083536728.png)



// 在执行函数中仍能使用try...catch..捕获错误

```javascript
let p1=new Promise((resolve,reject)=>{
  try{
    throw "err"
  }catch(e){
    console.log(e);
  }
  resolve()
})

setTimeout(console.log,0,p1)
```

![image-20220928083630773](C:\Users\35392\AppData\Roaming\Typora\typora-user-images\image-20220928083630773.png)





